
Orgzit
Great decision!
Check out Orgzit on your free trial account for 30 days. Get ready to join 1000+ business workers to experience a new level of information organization & collaboration.

    No credit card required
    No IT setup needed
    Start instantly

By signing up, you confirm that you've read and accepted our Terms of Service and Privacy Policy.
Already have an account? Sign in
Help us understand your business needs
What will you be using Orgzit for?
Which of the following best describes your business role?
What's your Company size?
What is the main thing that you want to manage?

Orgzit does not share your personal information with any external individual or company.
10 results are available, use up and down arrow keys to navigate.
Error
Error creating trial account.

{"error_message":"ConnectionError(<urllib3.connection.HTTPConnection object at 0x7f08561d6130>: Failed to establish a new connection: [Errno 111] Connection refused) caused by: NewConnectionError(<urllib3.connection.HTTPConnection object at 0x7f08561d6130>: Failed to establish a new connection: [Errno 111] Connection refused)","traceback":"Traceback (most recent call last):\n\n File \"/home/karanveer/orgzit/venv2/lib/python3.8/site-packages/urllib3/connection.py\", line 174, in _new_conn\n conn = connection.create_connection(\n\n File \"/home/karanveer/orgzit/venv2/lib/python3.8/site-packages/urllib3/util/connection.py\", line 95, in create_connection\n raise err\n\n File \"/home/karanveer/orgzit/venv2/lib/python3.8/site-packages/urllib3/util/connection.py\", line 85, in create_connection\n sock.connect(sa)\n\nConnectionRefusedError: [Errno 111] Connection refused\n\n\nDuring handling of the above exception, another exception occurred:\n\n\nTraceback (most recent call last):\n\n File \"/home/karanveer/orgzit/venv2/lib/python3.8/site-packages/elasticsearch/connection/http_urllib3.py\", line 115, in perform_request\n response = self.pool.urlopen(method, url, body, retries=False, headers=self.headers, **kw)\n\n File \"/home/karanveer/orgzit/venv2/lib/python3.8/site-packages/urllib3/connectionpool.py\", line 785, in urlopen\n retries = retries.increment(\n\n File \"/home/karanveer/orgzit/venv2/lib/python3.8/site-packages/urllib3/util/retry.py\", line 525, in increment\n raise six.reraise(type(error), error, _stacktrace)\n\n File \"/home/karanveer/orgzit/venv2/lib/python3.8/site-packages/urllib3/packages/six.py\", line 770, in reraise\n raise value\n\n File \"/home/karanveer/orgzit/venv2/lib/python3.8/site-packages/urllib3/connectionpool.py\", line 703, in urlopen\n httplib_response = self._make_request(\n\n File \"/home/karanveer/orgzit/venv2/lib/python3.8/site-packages/urllib3/connectionpool.py\", line 398, in _make_request\n conn.request(method, url, **httplib_request_kw)\n\n File \"/home/karanveer/orgzit/venv2/lib/python3.8/site-packages/urllib3/connection.py\", line 239, in request\n super(HTTPConnection, self).request(method, url, body=body, headers=headers)\n\n File \"/usr/lib/python3.8/http/client.py\", line 1252, in request\n self._send_request(method, url, body, headers, encode_chunked)\n\n File \"/usr/lib/python3.8/http/client.py\", line 1298, in _send_request\n self.endheaders(body, encode_chunked=encode_chunked)\n\n File \"/usr/lib/python3.8/http/client.py\", line 1247, in endheaders\n self._send_output(message_body, encode_chunked=encode_chunked)\n\n File \"/usr/lib/python3.8/http/client.py\", line 1007, in _send_output\n self.send(msg)\n\n File \"/usr/lib/python3.8/http/client.py\", line 947, in send\n self.connect()\n\n File \"/home/karanveer/orgzit/venv2/lib/python3.8/site-packages/urllib3/connection.py\", line 205, in connect\n conn = self._new_conn()\n\n File \"/home/karanveer/orgzit/venv2/lib/python3.8/site-packages/urllib3/connection.py\", line 186, in _new_conn\n raise NewConnectionError(\n\nurllib3.exceptions.NewConnectionError: : Failed to establish a new connection: [Errno 111] Connection refused\n\n\nDuring handling of the above exception, another exception occurred:\n\n\nTraceback (most recent call last):\n\n File \"/home/karanveer/orgzit/venv2/src/django-tastypie/tastypie/resources.py\", line 227, in wrapper\n response = callback(request, *args, **kwargs)\n\n File \"/home/karanveer/orgzit/apps/dataforms/api.py\", line 2018, in start_free_trial\n account.save()\n\n File \"/home/karanveer/orgzit/venv2/src/django-randomprimary/django_randomprimary/random_primary.py\", line 178, in save\n super(RandomPrimaryIdModel, self).save(*args, **kwargs)\n\n File \"/home/karanveer/orgzit/venv2/lib/python3.8/site-packages/django/db/models/base.py\", line 807, in save\n self.save_base(using=using, force_insert=force_insert,\n\n File \"/home/karanveer/orgzit/venv2/lib/python3.8/site-packages/django/db/models/base.py\", line 846, in save_base\n post_save.send(\n\n File \"/home/karanveer/orgzit/venv2/lib/python3.8/site-packages/django/dispatch/dispatcher.py\", line 191, in send\n return [\n\n File \"/home/karanveer/orgzit/venv2/lib/python3.8/site-packages/django/dispatch/dispatcher.py\", line 192, in \n (receiver, receiver(signal=self, sender=sender, **named))\n\n File \"/home/karanveer/orgzit/apps/dataforms/models_account.py\", line 530, in post_save\n SearchIndex.initialize_index(instance.subdomain)\n\n File \"/home/karanveer/orgzit/apps/dataforms/search.py\", line 69, in initialize_index\n read_alias_exists = es_client.indices.exists_alias(name=read_alias)\n\n File \"/home/karanveer/orgzit/venv2/lib/python3.8/site-packages/elasticsearch/client/utils.py\", line 73, in _wrapped\n return func(*args, params=params, **kwargs)\n\n File \"/home/karanveer/orgzit/venv2/lib/python3.8/site-packages/elasticsearch/client/indices.py\", line 375, in exists_alias\n return self.transport.perform_request('HEAD', _make_path(index, '_alias',\n\n File \"/home/karanveer/orgzit/venv2/lib/python3.8/site-packages/elasticsearch/transport.py\", line 312, in perform_request\n status, headers, data = connection.perform_request(method, url, params, body, ignore=ignore, timeout=timeout)\n\n File \"/home/karanveer/orgzit/venv2/lib/python3.8/site-packages/elasticsearch/connection/http_urllib3.py\", line 124, in perform_request\n raise ConnectionError('N/A', str(e), e)\n\nelasticsearch.exceptions.ConnectionError: ConnectionError(: Failed to establish a new connection: [Errno 111] Connection refused) caused by: NewConnectionError(: Failed to establish a new connection: [Errno 111] Connection refused)\n"}